<mujoco model="open_manipulator_x">
  <compiler angle="radian" autolimits="true"/>
  <option timestep="0.001"/>
  <asset>
    <mesh name="chain_link1" file="chain_link1.stl" scale="0.001 0.001 0.001"/>
    <mesh name="chain_link2" file="chain_link2.stl" scale="0.001 0.001 0.001"/>
    <mesh name="chain_link3" file="chain_link3.stl" scale="0.001 0.001 0.001"/>
    <mesh name="chain_link4" file="chain_link4.stl" scale="0.001 0.001 0.001"/>
    <mesh name="chain_link5" file="chain_link5.stl" scale="0.001 0.001 0.001"/>
    <mesh name="chain_link_grip_l" file="chain_link_grip_l.stl" scale="0.001 0.001 0.001"/>
    <mesh name="chain_link_grip_r" file="chain_link_grip_r.stl" scale="0.001 0.001 0.001"/>
  </asset>
    <asset>
    <texture type="skybox" builtin="gradient" rgb1="0.3 0.5 0.7" rgb2="0 0 0" width="512" height="3072"/>
    <texture type="2d" name="groundplane" builtin="checker" mark="edge" rgb1="0.2 0.3 0.4" rgb2="0.1 0.2 0.3"
      markrgb="0.8 0.8 0.8" width="300" height="300"/>
    <material name="groundplane" texture="groundplane" texuniform="true" texrepeat="5 5" reflectance="0.2"/>
  </asset>
  <visual>
    <headlight diffuse="0.6 0.6 0.6" ambient="0.3 0.3 0.3" specular="0 0 0"/>
    <rgba haze="0.15 0.25 0.35 1"/>
    <global azimuth="120" elevation="-20"/>
  </visual>
  <worldbody>
    <geom name="floor" size="0 0 0.05" type="plane" material="groundplane"/>
    <geom type="mesh" mesh="chain_link1" contype="0" conaffinity="0"/>
    <body name="link2" pos="0.012 0 0.017">
      <inertial pos="-0.000301849 0.000540437 0.000474335" quat="0.999915 0.000960074 0.0122201 -0.00449872" mass="0.0984068" diaginertia="3.4553e-05 3.26892e-05 1.88409e-05"/>
      <joint name="joint1" pos="0 0 0" axis="0 0 1" range="-2.82743 2.82743"/>
      <geom pos="0 0 0.019" type="mesh" mesh="chain_link2"/>
      <body name="link3" pos="0 0 0.0595">
        <inertial pos="0.0103084 0.000377434 0.101702" quat="0.71133 0.0466763 0.0513691 0.699423" mass="0.138509" diaginertia="0.000342915 0.000335932 5.49578e-05"/>
        <joint name="joint2" pos="0 0 0" axis="0 1 0" range="-1.79071 1.5708"/>
        <geom type="mesh" mesh="chain_link3"/>
        <body name="link4" pos="0.024 0 0.128">
          <inertial pos="0.0909096 0.000389298 0.000224133" quat="-0.00162881 0.706672 0.0026348 0.707535" mass="0.132746" diaginertia="0.000251551 0.000242311 3.06462e-05"/>
          <joint name="joint3" pos="0 0 0" axis="0 1 0" range="-0.942478 1.3823"/>
          <geom type="mesh" mesh="chain_link4"/>
          <body name="link5" pos="0.124 0 0">
            <inertial pos="0.0447737 3.65846e-07 0.00885244" quat="5.9604e-06 0.701608 -6.05347e-06 0.712564" mass="0.144276" diaginertia="0.00109978 0.0010827 0.00108095"/>
            <joint name="joint4" pos="0 0 0" axis="0 1 0" range="-1.79071 2.04204"/>
            <geom type="mesh" mesh="chain_link5"/>
            <site name="end_effector_link" pos="0.126 0. 0." />
            <body name="gripper_link" pos="0.0817 0.021 0">
              <inertial pos="0 0 0" mass="0.001" diaginertia="0.001 0.001 0.001"/>
              <joint name="gripper" pos="0 0 0" axis="0 1 0" type="slide" range="-0.01 0.019"/>
              <geom type="mesh" mesh="chain_link_grip_l"/>
            </body>
            <body name="gripper_link_sub" pos="0.0817 -0.021 0">
              <inertial pos="0 0 0" mass="0.001" diaginertia="0.001 0.001 0.001"/>
              <joint name="gripper_sub" pos="0 0 0" axis="0 -1 0" type="slide" range="-0.01 0.019"/>
              <geom type="mesh" mesh="chain_link_grip_r"/>
            </body>
          </body>
        </body>
      </body>
    </body>
  </worldbody>
  
  <equality>
    <joint joint1="gripper" joint2="gripper_sub" solimp="0.95 0.99 0.001" solref="0.005 1"/>
  </equality>

  <actuator>
    <motor name="actuator1" joint="joint1"/>
    <motor name="actuator2" joint="joint2"/>
    <motor name="actuator3" joint="joint3"/>
    <motor name="actuator4" joint="joint4"/>
    <motor name="actuator5" joint="gripper"/>
  </actuator>

</mujoco>
